#VRML_SIM R2023b utf8

PROTO Elevator [
field SFVec3f translation 0.0 0 0.0
field SFRotation rotation 0.0 0.0 0.0 0.0
]
{
Transform {
    translation IS translation
    rotation IS rotation
    children [
    Shape {
        geometry Mesh {
        url "models/Elevator.dae"
        }
        appearance Appearance {
        material Material {
            diffuseColor 0.4235 0.7882 0.2941
        }
        }
    },
    Transform {
        translation 0 0 0
        rotation 0 0 1 1.5708
        children [
        SliderJoint {
            jointParameters JointParameters {
            staticFriction 0.1
            dampingConstant 45.0
            axis 0 0 1
            maxStop 0.45
            minStop 0.0
            }
            device [
            PositionSensor {
                name "ElevatorPostionSensor"
            }
            LinearMotor {
                name "ElevatorMotor"
                maxForce 200
            }
            ]
            endPoint Solid {
            name "ElevatorSecondStage"
            translation 0 0 1
            children [
                Shape {
                geometry Mesh {
                    url "models/Elevator2.dae"
                }
                appearance Appearance {
                    material Material {
                    diffuseColor 0.4235 0.7882 0.2941
                    }
                }
                },
                Transform {
                translation 0 0 0
                rotation 0 0 0 0
                children [
                    SliderJoint {
                    jointParameters JointParameters {
                        staticFriction 0.1
                        dampingConstant 45.0
                        axis 0 0 1
                        maxStop 1.0
                        minStop 0.0
                    }
                    device [
                        PositionSensor {
                        name "ElevatorPostionSensor"
                        }
                        LinearMotor {
                        name "ElevatorMotorMiddle"
                        maxForce 200
                        }
                    ]
                    endPoint Solid {
                        name "ElevatorThirdStage"
                        translation 0 0 0
                        children [
                        Shape {
                            geometry Mesh {
                            url "models/Elevator2.dae"
                            }
                            appearance Appearance {
                            material Material {
                                diffuseColor 0.4235 0.7882 0.2941
                            }
                            }
                        },
                        Transform {
                            translation 0 0 0
                            rotation 0 0 0 0
                            children [
                            SliderJoint {
                                jointParameters JointParameters {
                                staticFriction 0.1
                                dampingConstant 45.0
                                axis 0 0 1
                                maxStop 1.0
                                minStop 0.0
                                }
                                device [
                                PositionSensor {
                                name "ElevatorPostionSensor"
                                }
                                LinearMotor {
                                name "ElevatorMotorUpper"
                                maxForce 200
                                }
                                ]
                            }
                            ]
                        }
                        ]
                        boundingObject Mesh {
                        url "models/Elevator.dae"
                        }
                        physics Physics {
                        density -1
                        mass 2.5
                        centerOfMass [0.0 0.0 0.0]
                        }
                    }
                    }
                ]
                }
            ]
            boundingObject Transform {
                translation 0.037 0.001 0
                rotation 0 0 1 1.5708
                children [
                Mesh {
                    url "models/Elevator.dae"
                }
                ]
            }
            physics Physics {
                density -1
                mass 2.5
                centerOfMass [0.0 0.0 0.0]
            }
            }
        }
        ]
    }
    ]
}
}
