#VRML_SIM R2023b utf8

EXTERNPROTO "https://raw.githubusercontent.com/cyberbotics/webots/R2023b/projects/appearances/protos/BrushedAluminium.proto"

PROTO RotationArm [
  field SFVec3f translation 0 0 0
  field SFRotation rotation 0 0 0 0
  field SFString rotationMotor "RotationMotor"
  field SFString rotationPositionSensor "RotationPositionSensor"


  
]
{
  Transform {
    translation IS translation
    rotation IS rotation
    children [
      CadShape {
        url "Models/RotationArm.dae"
      }
      Transform {
        translation 0 0 0
        rotation 0 1 0 1.57
        children [
          HingeJoint {
            jointParameters HingeJointParameters {
              axis 0 0 1
              staticFriction 0.01
              dampingConstant 0.1
            }
            device [
              PositionSensor {
                name IS rotationPositionSensor
              }
              RotationalMotor {
                name IS rotationMotor
                maxTorque 999999
              }
            ]
          }
        ]
      }
    ]
  }
}