#VRML_SIM R2023b utf8

EXTERNPROTO "https://raw.githubusercontent.com/cyberbotics/webots/R2023b/projects/appearances/protos/BrushedAluminium.proto"

PROTO RotationArm [
  field SFVec3f translation 0 0 0
  field SFRotation rotation 0 0 0 0
  field SFString rotationMotor "RotationMotor"
  field SFString rotationPositionSensor "RotationPositionSensor"
]
{
  Transform {
    translation IS translation
    rotation IS rotation
    children [
      HingeJoint {
        jointParameters HingeJointParameters {
          axis 1 0 0
          staticFriction 0.01
          dampingConstant 0.1
          anchor 0 0 0
        }
        device [
          PositionSensor {
            name IS rotationPositionSensor
          }
          RotationalMotor {
            name IS rotationMotor
            maxTorque 999999
          }
        ]
        endPoint Solid {
          name "RotationArmPart"
          children [
            CadShape {
              url "Models/RotationArm.dae"
            }
          ]
          physics Physics {
            density -1
            mass 0.5
            centerOfMass [0.0 0.0 0.0]
          }
          boundingObject Transform {
            rotation 0 1 0 1.5708
            children [
              Cylinder {
                radius 0.05
                height 0.10
              }
            ]
          }
        }
      }
    ]
  }
}
