#VRML_SIM R2023b utf8
# Describe the functionality of your PROTO here.
EXTERNPROTO "https://raw.githubusercontent.com/cyberbotics/webots/R2023b/projects/appearances/protos/BrushedAluminium.proto"

PROTO SwerveModule [
  field SFVec3f translation 0 0 0
  field SFRotation rotation 0 0 1 0

  field SFString name "Default Swerve Module"
  field SFString moduleMotorRotationName "Default Rotation Motor"
  field SFString moduleMotorDriveName "Default Drive Motor"
  field SFString moduleEncoderRotationName "Default Rotation Encoder Name"
  field SFString moduleEncoderDriveName "Default Drive Encoder Name"
  field SFVec3f RotationCoords 0.0 0.0 0.0
  field SFVec3f DriveCoords 0.0 0.0 0.0
]

{
  Transform {
    translation IS translation
    rotation IS rotation
    children [
      DEF MODULE_BOX_JOINT HingeJoint {
        jointParameters HingeJointParameters {
          anchor IS RotationCoords
          axis 0 0 1
          staticFriction 0.1
          dampingConstant 8.0
        }
        device [
          PositionSensor {
            name IS moduleEncoderRotationName
          }
          RotationalMotor {
            name IS moduleMotorRotationName
            maxTorque 999999
          }
        ]
        endPoint Solid {
          name IS name
          translation IS RotationCoords
          children [
            Shape {
              geometry Box {
                size 0.08 0.08 0.1
              }
            }
            DEF MODULE_CYLINDER_JOINT HingeJoint {
              jointParameters HingeJointParameters {
                anchor IS DriveCoords
                axis 0 1 0
                staticFriction 0.0
                dampingConstant 0.25
              }
              device [
                PositionSensor {
                  name IS moduleEncoderDriveName
                }
                RotationalMotor {
                  name IS moduleMotorDriveName
                  maxTorque 999999
                }
              ]
              endPoint Solid {
                translation IS DriveCoords
                rotation 1.0 0.0 0.0 1.57
                children [
                  Shape {
                    geometry Cylinder {
                      height 0.03732276
                      radius 0.035
                    }
                  }
                ]
                boundingObject Cylinder {
                  height 0.03732276
                  radius 0.035
                }
                physics Physics {
                  density -1
                  mass 0.5
                  centerOfMass [0.0 0.0 0.0]
                }
              }
            }
          ]
          boundingObject Box {
            size 0.08 0.08 0.1
          }
          physics Physics {
            density -1
            mass 2.0
            centerOfMass [0.0 0.0 0.0]
          }
        }
      }
    ]
  }
}
