#VRML_SIM R2023b utf8
# Describe the functionality of your PROTO here.
EXTERNPROTO "https://raw.githubusercontent.com/cyberbotics/webots/R2023b/projects/appearances/protos/BrushedAluminium.proto"

PROTO Shooter [
  field SFVec3f translation -0.15 0 0.07
  field SFRotation rotation 1.0 0.0 0.0 1.57
]

{
  Transform {
    translation IS translation
    rotation IS rotation
    children [
      DEF SHOOTER_JOINT HingeJoint {
        jointParameters HingeJointParameters {
          anchor 0 0 0
          axis 0 0 1
          staticFriction 0.1
          dampingConstant 0.5
        }
        
        device [
        PositionSensor {
        }          
        RotationalMotor {
            name "shooter_motor"
            maxTorque 999999
          }
        ]
        
        endPoint Solid {
          name "Shooter"
          translation 0 0 0
          children [
            Shape {
             appearance Appearance {
                material Material {
                  diffuseColor 0.31 0.78 0.47  # Red color (RGB)
                }
              }
              geometry Box {
                size 0.04 0.04 0.25
              }
            }           
          ]
          boundingObject Box {
                size 0.04 0.04 0.25
              }
          physics Physics {
            density -1
            mass 0.5
            centerOfMass [0.0 0.0 0.0]
          }
        }
      }
    ]
  }
}
