#VRML_SIM R2023b utf8
# Describe the functionality of your PROTO here.
EXTERNPROTO "https://raw.githubusercontent.com/cyberbotics/webots/R2023b/projects/appearances/protos/BrushedAluminium.proto"

PROTO SupportArms [
  field SFVec3f translationRight -0.295 -0.15 0.17
  field SFRotation rotationRight 0 0 1 0
  field SFVec3f translationLeft 0 0.35 0
  field SFRotation rotationLeft 0 0 1 0
  field MFString controllerArgs [
      "{\"type\": \"motor\", \"value\": {\"name\": \"front_right_rotation\", \"suffix\": \"\", \"model\": \"Falcon\", \"gear_ratio\": 21.4285714286, \"count\": 1, \"mechanically_inverted\": true}}",
      "{\"type\": \"motor\", \"value\": {\"name\": \"front_left_rotation\", \"suffix\": \"\", \"model\": \"Falcon\", \"gear_ratio\": 21.4285714286, \"count\": 1, \"mechanically_inverted\": true}}",
      "{\"type\": \"motor\", \"value\": {\"name\": \"back_right_rotation\", \"suffix\": \"\", \"model\": \"Falcon\", \"gear_ratio\": 21.4285714286, \"count\": 1, \"mechanically_inverted\": true}}",
      "{\"type\": \"motor\", \"value\": {\"name\": \"back_left_rotation\", \"suffix\": \"\", \"model\": \"Falcon\", \"gear_ratio\": 21.4285714286, \"count\": 1, \"mechanically_inverted\": true}}",
      
      "{\"type\": \"motor\", \"value\": {\"name\": \"front_right_drive\", \"suffix\": \"\", \"model\": \"Kraken\", \"gear_ratio\": 5.9027777, \"count\": 1, \"mechanically_inverted\": false}}",
      "{\"type\": \"motor\", \"value\": {\"name\": \"front_left_drive\", \"suffix\": \"\", \"model\": \"Kraken\", \"gear_ratio\": 5.9027777, \"count\": 1, \"mechanically_inverted\": false}}",
      "{\"type\": \"motor\", \"value\": {\"name\": \"back_right_drive\", \"suffix\": \"\", \"model\": \"Kraken\", \"gear_ratio\": 5.9027777, \"count\": 1, \"mechanically_inverted\": false}}",
      "{\"type\": \"motor\", \"value\": {\"name\": \"back_left_drive\", \"suffix\": \"\", \"model\": \"Kraken\", \"gear_ratio\": 5.9027777, \"count\": 1, \"mechanically_inverted\": false}}",
      
      "{\"type\": \"cancoder\", \"value\": {\"name\": \"front_right_cancoder\", \"inverted\": false, \"offsetDeg\": 0}}",
      "{\"type\": \"cancoder\", \"value\": {\"name\": \"front_left_cancoder\", \"inverted\": false, \"offsetDeg\": 0}}",
      "{\"type\": \"cancoder\", \"value\": {\"name\": \"back_right_cancoder\", \"inverted\": false, \"offsetDeg\": 0}}",
      "{\"type\": \"cancoder\", \"value\": {\"name\": \"back_left_cancoder\", \"inverted\": false, \"offsetDeg\": 0}}",

      "{\"type\": \"imu\", \"value\": {\"name\": \"imu\"}}"
  ]

]

{
  Transform {
    translation IS translationRight
    rotation IS rotationRight
    children [
      DEF SUPPORTARMS_JOINT_RIGHT HingeJoint {
        jointParameters HingeJointParameters {
          anchor -0.01 -0.01 -0.125
          axis 0 1 0
          maxStop 0.01
          minStop -1.57
          staticFriction 0.1
          dampingConstant 0.5
        }
        
        device [
        PositionSensor {
        }     
        RotationalMotor {
            name "support_arm_right"
            maxTorque 999999
          }
        ]
        
        endPoint Solid {
          name "Support Arm Right"          
          children [
            Shape {
             appearance Appearance {
                material Material {
                  diffuseColor 0.5 1 1        # Red color (RGB)
                }
              }
              geometry Box {
                size 0.02 0.02 0.25
              }
            }           
          ]
          boundingObject Box {
                size 0.02 0.02 0.25
              }
          physics Physics {
            density -1
            mass 0.5
            centerOfMass [0.0 0.0 0.0]
          }
        }
      }
    
    
    
  Transform {
    translation IS translationLeft
    rotation IS rotationLeft
    children [
      DEF SUPPORTARMS_JOINT_LEFT HingeJoint {
        jointParameters HingeJointParameters {
          anchor -0.01 -0.01 -0.125
          axis 0 1 0
          minStop -1.57
          maxStop 0.01
          staticFriction 0.1
          dampingConstant 0.5
        }
        
        device [
        PositionSensor {
        }     
        RotationalMotor {
            name "support_arm_left"
            maxTorque 999999
          }
        ]
        
        endPoint Solid {
          name "Support Arms Left"
          children [
            Shape {
             appearance Appearance {
                material Material {
                  diffuseColor 0.5 1 1  # Red color (RGB)
                }
              }
              geometry Box {
                size 0.02 0.02 0.25
              }
            }           
          ]
          boundingObject Box {
                size 0.02 0.02 0.25
              }
          physics Physics {
            density -1
            mass 0.5
            centerOfMass [0.0 0.0 0.0]
          }
        }
        }
        ]  
  }
      ]    
  }
}
