#VRML_SIM R2023b utf8
# Describe the functionality of your PROTO here.
EXTERNPROTO "https://raw.githubusercontent.com/cyberbotics/webots/R2023b/projects/appearances/protos/BrushedAluminium.proto"

PROTO SupportArms [
  field SFVec3f translationRight -0.295 -0.15 0.17
  field SFRotation rotationRight 0 0 1 0
  field SFVec3f translationLeft 0 0.35 0
  field SFRotation rotationLeft 0 0 1 0
]

{
  Transform {
    translation IS translationRight
    rotation IS rotationRight
    children [
      DEF SUPPORTARMS_JOINT_RIGHT HingeJoint {
        jointParameters HingeJointParameters {
          anchor -0.01 -0.01 -0.125
          axis 0 1 0
          maxStop 0.01
          minStop -1.57
          staticFriction 0.1
          dampingConstant 0.5
        }
        
        device [
        PositionSensor {
        }     
        RotationalMotor {
            name "support_arm_right"
            maxTorque 999999
          }
        ]
        
        endPoint Solid {
          name "Support Arm Right"          
          children [
            Shape {
             appearance Appearance {
                material Material {
                  diffuseColor 0.5 1 1  # Red color (RGB)
                }
              }
              geometry Box {
                size 0.02 0.02 0.25
              }
            }           
          ]
          boundingObject Box {
                size 0.02 0.02 0.25
              }
          physics Physics {
            density -1
            mass 0.5
            centerOfMass [0.0 0.0 0.0]
          }
        }
      }
    
    
    
  Transform {
    translation IS translationLeft
    rotation IS rotationLeft
    children [
      DEF SUPPORTARMS_JOINT_LEFT HingeJoint {
        jointParameters HingeJointParameters {
          anchor -0.01 -0.01 -0.125
          axis 0 1 0
          minStop -1.57
          maxStop 0.01
          staticFriction 0.1
          dampingConstant 0.5
        }
        
        device [
        PositionSensor {
        }     
        RotationalMotor {
            name "support_arm_left"
            maxTorque 999999
          }
        ]
        
        endPoint Solid {
          name "Support Arms Left"
          children [
            Shape {
             appearance Appearance {
                material Material {
                  diffuseColor 0.5 1 1  # Red color (RGB)
                }
              }
              geometry Box {
                size 0.02 0.02 0.25
              }
            }           
          ]
          boundingObject Box {
                size 0.02 0.02 0.25
              }
          physics Physics {
            density -1
            mass 0.5
            centerOfMass [0.0 0.0 0.0]
          }
        }
        }
        ]  
  }
      ]    
  }
}
